Workbook

Sheet GAs
A1: GA ID | B1: Name | C1: Description | D1: NHEQF Level
A2: GA1 | B2: Comprehensive Knowledge | C2: Deep understanding of scientific concepts | D2: 4.5
A3: GA2 | B3: Scientific Outlook | C3: Apply scientific principles to real-world problems | D3: 4.5
A4: GA3 | B4: Subject Expertise | C4: Mastery in biotechnology and genetics | D4: 4.5
A5: GA4 | B5: Critical Thinking & Problem Analysis | C5: Analyze and solve complex problems | D5: 5
A6: GA5 | B6: Teamwork and Accountability | C6: Collaborate effectively with accountability | D6: 5
A7: GA6 | B7: Communication Skills | C7: Communicate scientific ideas clearly | D7: 5
A8: GA7 | B8: Professionalism and Leadership Readiness | C8: Exhibit leadership in scientific tasks | D8: 5.5
A9: GA8 | B9: Intercultural and Ethical Competency | C9: Apply ethical and cultural principles | D9: 5.5
A10: GA9 | B10: Lifelong Learning | C10: Engage in continuous learning | D10: 6
A11: GA10 | B11: Environment Sustainability | C11: Address environmental issues | D11: 6
A12: GA11 | B12: Design/Develop Solutions | C12: Design innovative solutions | D12: 6

Sheet PEOs
A1: PEO ID | B1: Description | C1: GA1 | D1: GA2 | E1: GA3 | F1: GA4 | G1: GA5 | H1: GA6 | I1: GA7 | J1: GA8 | K1: GA9 | L1: GA10 | M1: GA11
A2: PEO1 | B2: Exhibit a spirit of scientific inquiry | C2: 3 | D2: 3 | E2: 2 | F2: 2 | G2: 0 | H2: 1 | I2: 1 | J2: 0 | K2: 0 | L2: 0 | M2: 0
A3: PEO2 | B3: Adapt to new technologies and methodologies | C3: 2 | D3: 2 | E3: 3 | F3: 1 | G3: 0 | H3: 0 | I3: 2 | J3: 0 | K3: 3 | L3: 0 | M3: 1
A4: PEO3 | B4: Analyze real life problems and design solutions | C4: 1 | D4: 1 | E4: 2 | F4: 3 | G4: 0 | H4: 0 | I4: 0 | J4: 0 | K4: 0 | L4: 0 | M4: 3
A5: PEO4 | B5: Apply ethical and social responsibilities | C5: 0 | D5: 0 | E5: 0 | F5: 0 | G5: 1 | H5: 2 | I5: 0 | J5: 3 | K5: 0 | L5: 2 | M5: 0
A6: PEO5 | B6: Create entrepreneurial mindset | C6: 0 | D6: 0 | E6: 1 | F6: 1 | G6: 2 | H6: 1 | I6: 3 | J6: 0 | K6: 2 | L6: 1 | M6: 2

Sheet POs & PSOs
A1: PO ID | B1: Description | C1: KSA Tag | D1: PEO1 | E1: PEO2 | F1: PEO3 | G1: PEO4 | H1: PEO5
A2: PO1 | B2: Propose novel ideas for solutions | C2: Knowledge | D2: 3 | E2: 1 | F2: 2 | G2: 0 | H2: 0
A3: PO2 | B3: Demonstrate scientific outlook | C3: Knowledge | D3: 3 | E3: 2 | F3: 1 | G3: 0 | H3: 0
A4: PO3 | B4: Analyze complex scientific problems | C4: Skill | D4: 2 | E4: 1 | F4: 3 | G4: 0 | H4: 0
A5: PO4 | B5: Comprehend and communicate concepts | C5: Skill | D5: 0 | E5: 1 | F5: 0 | G5: 2 | H5: 1
A6: PO5 | B6: Interpret scientific data critically | C6: Knowledge | D6: 2 | E6: 2 | F6: 2 | G6: 0 | H6: 0
A7: PO6 | B7: Demonstrate empathetic social concerns | C7: Attitude | D7: 0 | E7: 0 | F7: 1 | G7: 3 | H7: 1
A8: PO7 | B8: Imbibe ethical and moral values | C8: Attitude | D8: 0 | E8: 0 | F8: 0 | G8: 3 | H8: 0
A9: PO8 | B9: Address social and environmental issues | C9: Attitude | D9: 0 | E9: 0 | F9: 1 | G9: 2 | H9: 1
A10: PO9 | B10: Illustrate multidimensional skills | C10: Skill | D10: 0 | E10: 2 | F10: 0 | G10: 0 | H10: 3
A11: PSO1 | B11: Acquire interdisciplinary knowledge | C11: Skill | D11: 2 | E11: 1 | F11: 2 | G11: 0 | H11: 0
A12: PSO2 | B12: Attain multifaceted skill sets | C12: Skill | D12: 0 | E12: 2 | F12: 1 | G12: 0 | H12: 3
A13: PSO3 | B13: Explore career prospects in healthcare/research | C13: Knowledge | D13: 0 | E13: 1 | F13: 0 | G13: 0 | H13: 3

Sheet COs
A1: CO ID | B1: Statement | C1: KSA Tag | D1: KSA Level | E1: PO1 | F1: PO2 | G1: PO3 | H1: PO4 | I1: PO5 | J1: PO6 | K1: PO7 | L1: PO8 | M1: PO9 | N1: PSO1 | O1: PSO2 | P1: PSO3
A2: CO01 | B2: Understand various concepts of plant physiology and photobiology | C2: Knowledge | D2: K1 | E2: 3 | F2: 2 | G2: 0 | H2: 1 | I2: 1 | J2: 0 | K2: 0 | L2: 0 | M2: 0 | N2: 2 | O2: 0 | P2: 0
A3: CO02 | B3: Analyse and assess the mechanism of physiology of stress in plant systems | C3: Knowledge | D3: K2 | E3: 2 | F3: 1 | G3: 3 | H3: 0 | I3: 2 | J3: 0 | K3: 0 | L3: 0 | M3: 0 | N3: 1 | O3: 1 | P3: 0
A4: CO03 | B4: Identify the role of different growth regulators and media constituents in development | C4: Skill | D4: S1 | E4: 0 | F4: 0 | G4: 1 | H4: 1 | I4: 0 | J4: 0 | K4: 0 | L4: 1 | M4: 2 | N4: 2 | O4: 2 | P4: 1
A5: CO04 | B5: Apply techniques of micropropagation for ex situ conservation | C5: Skill | D5: S1 | E5: 0 | F5: 0 | G5: 0 | H5: 2 | I5: 0 | J5: 1 | K5: 1 | L5: 1 | M5: 2 | N5: 1 | O5: 3 | P5: 2

Sheet Assessments
A1: Assessment Name | B1: Max Marks | C1: CO01 | D1: CO02 | E1: CO03 | F1: CO04 | G1: Threshold (%)
A2: Attendance | B2: 5 | C2: 0.25 | D2: 0.25 | E2: 0.25 | F2: 0.25 | G2: 65
A3: Class Participation | B3: 5 | C3: 0.25 | D3: 0.25 | E3: 0.25 | F3: 0.25 | G3: 65
A4: Midterm | B4: 10 | C4: 0.35 | D4: 0.35 | E4: 0.15 | F4: 0.15 | G4: 65
A5: Activity 1 | B5: 15 | C5: 0.1 | D5: 0.5 | E5: 0.2 | F5: 0.2 | G5: 65
A6: Activity 2 | B6: 15 | C6: 0.35 | D6: 0.35 | E6: 0.15 | F6: 0.15 | G6: 65
A7: End Semester Exam | B7: 50 | C7: 0.35 | D7: 0.35 | E7: 0.15 | F7: 0.15 | G7: 65
A8: Max Score | C8: =(B2*C2) + (B3*C3) + (B4*C4) + (B5*C5) + (B6*C6) -> 12.75 | D8: =(B2*D2) + (B3*D3) + (B4*D4) + (B5*D5) + (B6*D6) -> 18.75 | E8: =(B2*E2) + (B3*E3) + (B4*E4) + (B5*E5) + (B6*E6) -> 9.25 | F8: =(B2*F2) + (B3*F3) + (B4*F4) + (B5*F5) + (B6*F6) -> 9.25 | H8: =SUM(C8:F8) -> 50
A9: threshold score | C9: =C8*$G$7/100 -> 8.2875 | D9: =D8*$G$7/100 -> 12.1875 | E9: =E8*$G$7/100 -> 6.0125 | F9: =F8*$G$7/100 -> 6.0125 | H9: =SUM(C9:F9) -> 32.5
A11: K | C11: =C8*0.9 -> 11.475 | D11: =D8*0.7 -> 13.125 | E11: =E8*0.4 -> 3.7 | F11: =F8*0.4 -> 3.7 | H11: =SUM(C11:F11) -> 32 | I11: =H11*G7/100 -> 20.8
A12: S | C12: =0.05*C8 -> 0.6375 | D12: =D8*0.15 -> 2.8125 | E12: =E8*0.5 -> 4.625 | F12: =F8*0.5 -> 4.625 | H12: =SUM(C12:F12) -> 12.7 | I12: =H12*$G$7/100 -> 8.255
A13: A | C13: =0.05*C8 -> 0.6375 | D13: =D8*0.15 -> 2.8125 | E13: =E8*0.1 -> 0.925 | F13: =F8*0.1 -> 0.925 | H13: =SUM(C13:F13) -> 5.3 | I13: =H13*$G$7/100 -> 3.445

Sheet IA Marks
D1: TOTAL MID TERM | E1: ACTIVITY 1 | F1: ACTIVITY 2 | G1: CLASS PARTICIPATION | H1: ATTENDANCE
A2: S N | B2: USN NO | C2: STUDENT NAME | D2: 10 MARKS | E2: 15 MARKS | F2: 15 MARKS | G2: 5 MARKS | H2: 5 MARKS
A3: 1 | B3: 22BSR16003 | C3: ANANYA SURESH | D3: 8.3 | E3: 12 | F3: 13 | G3: 4 | H3: 3
A4: 2 | B4: 22BSR16005 | C4: MANYA MAHESHWARI | D4: 8.25 | E4: 12 | F4: 13 | G4: 4 | H4: 3
A5: 3 | B5: 22BSR16006 | C5: PRERANA IYENGAR K L | D5: 9.5 | E5: 12.5 | F5: 14 | G5: 5 | H5: 5
A6: 4 | B6: 22BSR16025 | C6: DHARANESHWAR G | D6: 6.45 | E6: 10.5 | F6: 14 | G6: 4.5 | H6: 3
A7: 5 | B7: 22BSR16028 | C7: ARDRA R | D7: 7.3 | E7: 11.5 | F7: 13.5 | G7: 4.5 | H7: 5
A8: 6 | B8: 22BSR16030 | C8: KRUTHIKA S | D8: 6.3 | E8: 11 | F8: 13.5 | G8: 4 | H8: 3
A9: 7 | B9: 22BSR16038 | C9: KESANI DEEKSHITHA | D9: 7.35 | E9: 11 | F9: 13.5 | G9: 4.5 | H9: 3
A10: 8 | B10: 22BSR16040 | C10: PALLE KUSUMA KUMARI | D10: 4.4 | E10: 11 | F10: 12 | G10: 3.5 | H10: 3
A11: 9 | B11: 22BSR16043 | C11: FAIZULLAH | D11: 4.6 | E11: 11 | F11: 12 | G11: 3.5 | H11: 3
A12: 10 | B12: 22BSR16044 | C12: KALAIVI V | D12: 8.2 | E12: 11.5 | F12: 14 | G12: 4.5 | H12: 5
A13: 11 | B13: 22BSR16073 | C13: MANISH D | D13: 6.3 | E13: 11.5 | F13: 14 | G13: 3.5 | H13: 3
A14: 12 | B14: 22BSR16075 | C14: GOPIKA SURESH | D14: 8.8 | E14: 11.5 | F14: 14 | G14: 5 | H14: 5
A15: 13 | B15: 22BSR16087 | C15: SAATVIK TYAGI | D15: 4.4 | E15: 11.5 | F15: 12.5 | G15: 3 | H15: 3

Sheet Componentwise marks
A1: USN No | B1: Name | D1: Attendance | H1: CP | L1: MT | P1: ACT1 | T1: ACT2
C2: Course ID | D2: CO01 | E2: CO02 | F2: CO03 | G2: CO04 | H2: CO01 | I2: CO02 | J2: CO03 | K2: CO04 | L2: CO01 | M2: CO02 | N2: CO03 | O2: CO04 | P2: CO01 | Q2: CO02 | R2: CO03 | S2: CO04 | T2: CO01 | U2: CO02 | V2: CO03 | W2: CO04
A3: 22BSR16003 | B3: ANANYA SURESH | C3: 22BT6D102 | D3: =Assessments!$C$2*'IA Marks'!H3 -> 0.75 | E3: =Assessments!$D$2*'IA Marks'!H3 -> 0.75 | F3: =Assessments!$E$2*'IA Marks'!H3 -> 0.75 | G3: =Assessments!$F$2*'IA Marks'!H3 -> 0.75 | H3: =Assessments!$C$3*'IA Marks'!G3 -> 1 | I3: =Assessments!$D$3*'IA Marks'!G3 -> 1 | J3: =Assessments!$E$3*'IA Marks'!G3 -> 1 | K3: =Assessments!$F$3*'IA Marks'!G3 -> 1 | L3: =Assessments!$C$4*'IA Marks'!D3 -> 2.905 | M3: =Assessments!$D$4*'IA Marks'!D3 -> 2.905 | N3: =Assessments!$E$4*'IA Marks'!D3 -> 1.245 | O3: =Assessments!$F$4*'IA Marks'!D3 -> 1.245 | P3: =Assessments!$C$5*'IA Marks'!E3 -> 1.2 | Q3: =Assessments!$D$5*'IA Marks'!E3 -> 6 | R3: =Assessments!$E$5*'IA Marks'!E3 -> 2.4 | S3: =Assessments!$F$5*'IA Marks'!E3 -> 2.4 | T3: =Assessments!$C$6*'IA Marks'!F3 -> 4.55 | U3: =Assessments!$D$6*'IA Marks'!F3 -> 4.55 | V3: =Assessments!$E$6*'IA Marks'!F3 -> 1.95 | W3: =Assessments!$F$6*'IA Marks'!F3 -> 1.95
A4: 22BSR16005 | B4: MANYA MAHESHWARI | C4: 22BT6D103 | D4: =Assessments!$C$2*'IA Marks'!H4 -> 0.75 | E4: =Assessments!$D$2*'IA Marks'!H4 -> 0.75 | F4: =Assessments!$E$2*'IA Marks'!H4 -> 0.75 | G4: =Assessments!$F$2*'IA Marks'!H4 -> 0.75 | H4: =Assessments!$C$3*'IA Marks'!G4 -> 1 | I4: =Assessments!$D$3*'IA Marks'!G4 -> 1 | J4: =Assessments!$E$3*'IA Marks'!G4 -> 1 | K4: =Assessments!$F$3*'IA Marks'!G4 -> 1 | L4: =Assessments!$C$4*'IA Marks'!D4 -> 2.8875 | M4: =Assessments!$D$4*'IA Marks'!D4 -> 2.8875 | N4: =Assessments!$E$4*'IA Marks'!D4 -> 1.2375 | O4: =Assessments!$F$4*'IA Marks'!D4 -> 1.2375 | P4: =Assessments!$C$5*'IA Marks'!E4 -> 1.2 | Q4: =Assessments!$D$5*'IA Marks'!E4 -> 6 | R4: =Assessments!$E$5*'IA Marks'!E4 -> 2.4 | S4: =Assessments!$F$5*'IA Marks'!E4 -> 2.4 | T4: =Assessments!$C$6*'IA Marks'!F4 -> 4.55 | U4: =Assessments!$D$6*'IA Marks'!F4 -> 4.55 | V4: =Assessments!$E$6*'IA Marks'!F4 -> 1.95 | W4: =Assessments!$F$6*'IA Marks'!F4 -> 1.95
A5: 22BSR16006 | B5: PRERANA IYENGAR K L | C5: 22BT6D104 | D5: =Assessments!$C$2*'IA Marks'!H5 -> 1.25 | E5: =Assessments!$D$2*'IA Marks'!H5 -> 1.25 | F5: =Assessments!$E$2*'IA Marks'!H5 -> 1.25 | G5: =Assessments!$F$2*'IA Marks'!H5 -> 1.25 | H5: =Assessments!$C$3*'IA Marks'!G5 -> 1.25 | I5: =Assessments!$D$3*'IA Marks'!G5 -> 1.25 | J5: =Assessments!$E$3*'IA Marks'!G5 -> 1.25 | K5: =Assessments!$F$3*'IA Marks'!G5 -> 1.25 | L5: =Assessments!$C$4*'IA Marks'!D5 -> 3.325 | M5: =Assessments!$D$4*'IA Marks'!D5 -> 3.325 | N5: =Assessments!$E$4*'IA Marks'!D5 -> 1.425 | O5: =Assessments!$F$4*'IA Marks'!D5 -> 1.425 | P5: =Assessments!$C$5*'IA Marks'!E5 -> 1.25 | Q5: =Assessments!$D$5*'IA Marks'!E5 -> 6.25 | R5: =Assessments!$E$5*'IA Marks'!E5 -> 2.5 | S5: =Assessments!$F$5*'IA Marks'!E5 -> 2.5 | T5: =Assessments!$C$6*'IA Marks'!F5 -> 4.9 | U5: =Assessments!$D$6*'IA Marks'!F5 -> 4.9 | V5: =Assessments!$E$6*'IA Marks'!F5 -> 2.1 | W5: =Assessments!$F$6*'IA Marks'!F5 -> 2.1
A6: 22BSR16025 | B6: DHARANESHWAR G | C6: 22BT6D105 | D6: =Assessments!$C$2*'IA Marks'!H6 -> 0.75 | E6: =Assessments!$D$2*'IA Marks'!H6 -> 0.75 | F6: =Assessments!$E$2*'IA Marks'!H6 -> 0.75 | G6: =Assessments!$F$2*'IA Marks'!H6 -> 0.75 | H6: =Assessments!$C$3*'IA Marks'!G6 -> 1.125 | I6: =Assessments!$D$3*'IA Marks'!G6 -> 1.125 | J6: =Assessments!$E$3*'IA Marks'!G6 -> 1.125 | K6: =Assessments!$F$3*'IA Marks'!G6 -> 1.125 | L6: =Assessments!$C$4*'IA Marks'!D6 -> 2.2575 | M6: =Assessments!$D$4*'IA Marks'!D6 -> 2.2575 | N6: =Assessments!$E$4*'IA Marks'!D6 -> 0.9675 | O6: =Assessments!$F$4*'IA Marks'!D6 -> 0.9675 | P6: =Assessments!$C$5*'IA Marks'!E6 -> 1.05 | Q6: =Assessments!$D$5*'IA Marks'!E6 -> 5.25 | R6: =Assessments!$E$5*'IA Marks'!E6 -> 2.1 | S6: =Assessments!$F$5*'IA Marks'!E6 -> 2.1 | T6: =Assessments!$C$6*'IA Marks'!F6 -> 4.9 | U6: =Assessments!$D$6*'IA Marks'!F6 -> 4.9 | V6: =Assessments!$E$6*'IA Marks'!F6 -> 2.1 | W6: =Assessments!$F$6*'IA Marks'!F6 -> 2.1
A7: 22BSR16028 | B7: ARDRA R | C7: 22BT6D106 | D7: =Assessments!$C$2*'IA Marks'!H7 -> 1.25 | E7: =Assessments!$D$2*'IA Marks'!H7 -> 1.25 | F7: =Assessments!$E$2*'IA Marks'!H7 -> 1.25 | G7: =Assessments!$F$2*'IA Marks'!H7 -> 1.25 | H7: =Assessments!$C$3*'IA Marks'!G7 -> 1.125 | I7: =Assessments!$D$3*'IA Marks'!G7 -> 1.125 | J7: =Assessments!$E$3*'IA Marks'!G7 -> 1.125 | K7: =Assessments!$F$3*'IA Marks'!G7 -> 1.125 | L7: =Assessments!$C$4*'IA Marks'!D7 -> 2.555 | M7: =Assessments!$D$4*'IA Marks'!D7 -> 2.555 | N7: =Assessments!$E$4*'IA Marks'!D7 -> 1.095 | O7: =Assessments!$F$4*'IA Marks'!D7 -> 1.095 | P7: =Assessments!$C$5*'IA Marks'!E7 -> 1.15 | Q7: =Assessments!$D$5*'IA Marks'!E7 -> 5.75 | R7: =Assessments!$E$5*'IA Marks'!E7 -> 2.3 | S7: =Assessments!$F$5*'IA Marks'!E7 -> 2.3 | T7: =Assessments!$C$6*'IA Marks'!F7 -> 4.725 | U7: =Assessments!$D$6*'IA Marks'!F7 -> 4.725 | V7: =Assessments!$E$6*'IA Marks'!F7 -> 2.025 | W7: =Assessments!$F$6*'IA Marks'!F7 -> 2.025
A8: 22BSR16030 | B8: KRUTHIKA S | C8: 22BT6D107 | D8: =Assessments!$C$2*'IA Marks'!H8 -> 0.75 | E8: =Assessments!$D$2*'IA Marks'!H8 -> 0.75 | F8: =Assessments!$E$2*'IA Marks'!H8 -> 0.75 | G8: =Assessments!$F$2*'IA Marks'!H8 -> 0.75 | H8: =Assessments!$C$3*'IA Marks'!G8 -> 1 | I8: =Assessments!$D$3*'IA Marks'!G8 -> 1 | J8: =Assessments!$E$3*'IA Marks'!G8 -> 1 | K8: =Assessments!$F$3*'IA Marks'!G8 -> 1 | L8: =Assessments!$C$4*'IA Marks'!D8 -> 2.205 | M8: =Assessments!$D$4*'IA Marks'!D8 -> 2.205 | N8: =Assessments!$E$4*'IA Marks'!D8 -> 0.945 | O8: =Assessments!$F$4*'IA Marks'!D8 -> 0.945 | P8: =Assessments!$C$5*'IA Marks'!E8 -> 1.1 | Q8: =Assessments!$D$5*'IA Marks'!E8 -> 5.5 | R8: =Assessments!$E$5*'IA Marks'!E8 -> 2.2 | S8: =Assessments!$F$5*'IA Marks'!E8 -> 2.2 | T8: =Assessments!$C$6*'IA Marks'!F8 -> 4.725 | U8: =Assessments!$D$6*'IA Marks'!F8 -> 4.725 | V8: =Assessments!$E$6*'IA Marks'!F8 -> 2.025 | W8: =Assessments!$F$6*'IA Marks'!F8 -> 2.025
A9: 22BSR16038 | B9: KESANI DEEKSHITHA | C9: 22BT6D108 | D9: =Assessments!$C$2*'IA Marks'!H9 -> 0.75 | E9: =Assessments!$D$2*'IA Marks'!H9 -> 0.75 | F9: =Assessments!$E$2*'IA Marks'!H9 -> 0.75 | G9: =Assessments!$F$2*'IA Marks'!H9 -> 0.75 | H9: =Assessments!$C$3*'IA Marks'!G9 -> 1.125 | I9: =Assessments!$D$3*'IA Marks'!G9 -> 1.125 | J9: =Assessments!$E$3*'IA Marks'!G9 -> 1.125 | K9: =Assessments!$F$3*'IA Marks'!G9 -> 1.125 | L9: =Assessments!$C$4*'IA Marks'!D9 -> 2.5725 | M9: =Assessments!$D$4*'IA Marks'!D9 -> 2.5725 | N9: =Assessments!$E$4*'IA Marks'!D9 -> 1.1025 | O9: =Assessments!$F$4*'IA Marks'!D9 -> 1.1025 | P9: =Assessments!$C$5*'IA Marks'!E9 -> 1.1 | Q9: =Assessments!$D$5*'IA Marks'!E9 -> 5.5 | R9: =Assessments!$E$5*'IA Marks'!E9 -> 2.2 | S9: =Assessments!$F$5*'IA Marks'!E9 -> 2.2 | T9: =Assessments!$C$6*'IA Marks'!F9 -> 4.725 | U9: =Assessments!$D$6*'IA Marks'!F9 -> 4.725 | V9: =Assessments!$E$6*'IA Marks'!F9 -> 2.025 | W9: =Assessments!$F$6*'IA Marks'!F9 -> 2.025
A10: 22BSR16040 | B10: PALLE KUSUMA KUMARI | C10: 22BT6D109 | D10: =Assessments!$C$2*'IA Marks'!H10 -> 0.75 | E10: =Assessments!$D$2*'IA Marks'!H10 -> 0.75 | F10: =Assessments!$E$2*'IA Marks'!H10 -> 0.75 | G10: =Assessments!$F$2*'IA Marks'!H10 -> 0.75 | H10: =Assessments!$C$3*'IA Marks'!G10 -> 0.875 | I10: =Assessments!$D$3*'IA Marks'!G10 -> 0.875 | J10: =Assessments!$E$3*'IA Marks'!G10 -> 0.875 | K10: =Assessments!$F$3*'IA Marks'!G10 -> 0.875 | L10: =Assessments!$C$4*'IA Marks'!D10 -> 1.54 | M10: =Assessments!$D$4*'IA Marks'!D10 -> 1.54 | N10: =Assessments!$E$4*'IA Marks'!D10 -> 0.66 | O10: =Assessments!$F$4*'IA Marks'!D10 -> 0.66 | P10: =Assessments!$C$5*'IA Marks'!E10 -> 1.1 | Q10: =Assessments!$D$5*'IA Marks'!E10 -> 5.5 | R10: =Assessments!$E$5*'IA Marks'!E10 -> 2.2 | S10: =Assessments!$F$5*'IA Marks'!E10 -> 2.2 | T10: =Assessments!$C$6*'IA Marks'!F10 -> 4.2 | U10: =Assessments!$D$6*'IA Marks'!F10 -> 4.2 | V10: =Assessments!$E$6*'IA Marks'!F10 -> 1.8 | W10: =Assessments!$F$6*'IA Marks'!F10 -> 1.8
A11: 22BSR16043 | B11: FAIZULLAH | C11: 22BT6D110 | D11: =Assessments!$C$2*'IA Marks'!H11 -> 0.75 | E11: =Assessments!$D$2*'IA Marks'!H11 -> 0.75 | F11: =Assessments!$E$2*'IA Marks'!H11 -> 0.75 | G11: =Assessments!$F$2*'IA Marks'!H11 -> 0.75 | H11: =Assessments!$C$3*'IA Marks'!G11 -> 0.875 | I11: =Assessments!$D$3*'IA Marks'!G11 -> 0.875 | J11: =Assessments!$E$3*'IA Marks'!G11 -> 0.875 | K11: =Assessments!$F$3*'IA Marks'!G11 -> 0.875 | L11: =Assessments!$C$4*'IA Marks'!D11 -> 1.61 | M11: =Assessments!$D$4*'IA Marks'!D11 -> 1.61 | N11: =Assessments!$E$4*'IA Marks'!D11 -> 0.69 | O11: =Assessments!$F$4*'IA Marks'!D11 -> 0.69 | P11: =Assessments!$C$5*'IA Marks'!E11 -> 1.1 | Q11: =Assessments!$D$5*'IA Marks'!E11 -> 5.5 | R11: =Assessments!$E$5*'IA Marks'!E11 -> 2.2 | S11: =Assessments!$F$5*'IA Marks'!E11 -> 2.2 | T11: =Assessments!$C$6*'IA Marks'!F11 -> 4.2 | U11: =Assessments!$D$6*'IA Marks'!F11 -> 4.2 | V11: =Assessments!$E$6*'IA Marks'!F11 -> 1.8 | W11: =Assessments!$F$6*'IA Marks'!F11 -> 1.8
A12: 22BSR16044 | B12: KALAIVI V | C12: 22BT6D111 | D12: =Assessments!$C$2*'IA Marks'!H12 -> 1.25 | E12: =Assessments!$D$2*'IA Marks'!H12 -> 1.25 | F12: =Assessments!$E$2*'IA Marks'!H12 -> 1.25 | G12: =Assessments!$F$2*'IA Marks'!H12 -> 1.25 | H12: =Assessments!$C$3*'IA Marks'!G12 -> 1.125 | I12: =Assessments!$D$3*'IA Marks'!G12 -> 1.125 | J12: =Assessments!$E$3*'IA Marks'!G12 -> 1.125 | K12: =Assessments!$F$3*'IA Marks'!G12 -> 1.125 | L12: =Assessments!$C$4*'IA Marks'!D12 -> 2.87 | M12: =Assessments!$D$4*'IA Marks'!D12 -> 2.87 | N12: =Assessments!$E$4*'IA Marks'!D12 -> 1.23 | O12: =Assessments!$F$4*'IA Marks'!D12 -> 1.23 | P12: =Assessments!$C$5*'IA Marks'!E12 -> 1.15 | Q12: =Assessments!$D$5*'IA Marks'!E12 -> 5.75 | R12: =Assessments!$E$5*'IA Marks'!E12 -> 2.3 | S12: =Assessments!$F$5*'IA Marks'!E12 -> 2.3 | T12: =Assessments!$C$6*'IA Marks'!F12 -> 4.9 | U12: =Assessments!$D$6*'IA Marks'!F12 -> 4.9 | V12: =Assessments!$E$6*'IA Marks'!F12 -> 2.1 | W12: =Assessments!$F$6*'IA Marks'!F12 -> 2.1
A13: 22BSR16073 | B13: MANISH D | C13: 22BT6D112 | D13: =Assessments!$C$2*'IA Marks'!H13 -> 0.75 | E13: =Assessments!$D$2*'IA Marks'!H13 -> 0.75 | F13: =Assessments!$E$2*'IA Marks'!H13 -> 0.75 | G13: =Assessments!$F$2*'IA Marks'!H13 -> 0.75 | H13: =Assessments!$C$3*'IA Marks'!G13 -> 0.875 | I13: =Assessments!$D$3*'IA Marks'!G13 -> 0.875 | J13: =Assessments!$E$3*'IA Marks'!G13 -> 0.875 | K13: =Assessments!$F$3*'IA Marks'!G13 -> 0.875 | L13: =Assessments!$C$4*'IA Marks'!D13 -> 2.205 | M13: =Assessments!$D$4*'IA Marks'!D13 -> 2.205 | N13: =Assessments!$E$4*'IA Marks'!D13 -> 0.945 | O13: =Assessments!$F$4*'IA Marks'!D13 -> 0.945 | P13: =Assessments!$C$5*'IA Marks'!E13 -> 1.15 | Q13: =Assessments!$D$5*'IA Marks'!E13 -> 5.75 | R13: =Assessments!$E$5*'IA Marks'!E13 -> 2.3 | S13: =Assessments!$F$5*'IA Marks'!E13 -> 2.3 | T13: =Assessments!$C$6*'IA Marks'!F13 -> 4.9 | U13: =Assessments!$D$6*'IA Marks'!F13 -> 4.9 | V13: =Assessments!$E$6*'IA Marks'!F13 -> 2.1 | W13: =Assessments!$F$6*'IA Marks'!F13 -> 2.1
A14: 22BSR16075 | B14: GOPIKA SURESH | C14: 22BT6D113 | D14: =Assessments!$C$2*'IA Marks'!H14 -> 1.25 | E14: =Assessments!$D$2*'IA Marks'!H14 -> 1.25 | F14: =Assessments!$E$2*'IA Marks'!H14 -> 1.25 | G14: =Assessments!$F$2*'IA Marks'!H14 -> 1.25 | H14: =Assessments!$C$3*'IA Marks'!G14 -> 1.25 | I14: =Assessments!$D$3*'IA Marks'!G14 -> 1.25 | J14: =Assessments!$E$3*'IA Marks'!G14 -> 1.25 | K14: =Assessments!$F$3*'IA Marks'!G14 -> 1.25 | L14: =Assessments!$C$4*'IA Marks'!D14 -> 3.08 | M14: =Assessments!$D$4*'IA Marks'!D14 -> 3.08 | N14: =Assessments!$E$4*'IA Marks'!D14 -> 1.32 | O14: =Assessments!$F$4*'IA Marks'!D14 -> 1.32 | P14: =Assessments!$C$5*'IA Marks'!E14 -> 1.15 | Q14: =Assessments!$D$5*'IA Marks'!E14 -> 5.75 | R14: =Assessments!$E$5*'IA Marks'!E14 -> 2.3 | S14: =Assessments!$F$5*'IA Marks'!E14 -> 2.3 | T14: =Assessments!$C$6*'IA Marks'!F14 -> 4.9 | U14: =Assessments!$D$6*'IA Marks'!F14 -> 4.9 | V14: =Assessments!$E$6*'IA Marks'!F14 -> 2.1 | W14: =Assessments!$F$6*'IA Marks'!F14 -> 2.1
A15: 22BSR16087 | B15: SAATVIK TYAGI | C15: 22BT6D114 | D15: =Assessments!$C$2*'IA Marks'!H15 -> 0.75 | E15: =Assessments!$D$2*'IA Marks'!H15 -> 0.75 | F15: =Assessments!$E$2*'IA Marks'!H15 -> 0.75 | G15: =Assessments!$F$2*'IA Marks'!H15 -> 0.75 | H15: =Assessments!$C$3*'IA Marks'!G15 -> 0.75 | I15: =Assessments!$D$3*'IA Marks'!G15 -> 0.75 | J15: =Assessments!$E$3*'IA Marks'!G15 -> 0.75 | K15: =Assessments!$F$3*'IA Marks'!G15 -> 0.75 | L15: =Assessments!$C$4*'IA Marks'!D15 -> 1.54 | M15: =Assessments!$D$4*'IA Marks'!D15 -> 1.54 | N15: =Assessments!$E$4*'IA Marks'!D15 -> 0.66 | O15: =Assessments!$F$4*'IA Marks'!D15 -> 0.66 | P15: =Assessments!$C$5*'IA Marks'!E15 -> 1.15 | Q15: =Assessments!$D$5*'IA Marks'!E15 -> 5.75 | R15: =Assessments!$E$5*'IA Marks'!E15 -> 2.3 | S15: =Assessments!$F$5*'IA Marks'!E15 -> 2.3 | T15: =Assessments!$C$6*'IA Marks'!F15 -> 4.375 | U15: =Assessments!$D$6*'IA Marks'!F15 -> 4.375 | V15: =Assessments!$E$6*'IA Marks'!F15 -> 1.875 | W15: =Assessments!$F$6*'IA Marks'!F15 -> 1.875

Sheet Copy of Calculations_new
A1: USN No | B1: Student Name | C1: CO01_Score | D1: CO01_Attainment | E1: CO02_Score | F1: CO02_Attainment | G1: CO03_Score | H1: CO03_Attainment | I1: CO04_Score | J1: CO04_Attainment | K1: CO01_Knowledge | L1: CO01_Skill | M1: CO01_Attitude | N1: CO02_Knowledge | O1: CO02_Skill | P1: CO02_Attitude | Q1: CO03_Knowledge | R1: CO03_Skill | S1: CO03_Attitude | T1: CO04_Knowledge | U1: CO04_Skill | V1: CO04_Attitude | W1: CO_Knowledge_Score | X1: CO_Knowledge_Attainment | Y1: CO_Skill_Score | Z1: CO_Skill_attainment | AA1: CO_Attitude_Score | AB1: CO_Attitude_Attainment | AC1: PO1_Score | AD1: PO1_Attainment | AE1: PO2_Score | AF1: PO2_attainment | AG1: PO3_Score | AH1: PO3_attainment | AI1: PO4_Score | AJ1: PO4_attainment | AK1: PO5_Score | AL1: PO5_attainment | AM1: PO6_score | AN1: PO6_attainment | AO1: PO7_Score | AP1: PO7_attainment | AQ1: PO8_Score | AR1: PO8_attainment | AS1: PO9_Score | AT1: PO9_attainment | AU1: PSO1_Score | AV1: PSO1_attainment | AW1: PSO2_Score | AX1: PSO2_attainment | AY1: PSO3_Score | AZ1: PSO3_attainment
A2: ='IA Marks'!B3 -> 22BSR16003 | B2: ='IA Marks'!C3 -> ANANYA SURESH | C2: =('Componentwise marks'!D3 + 'Componentwise marks'!H3 + 'Componentwise marks'!L3 + 'Componentwise marks'!P3 + 'Componentwise marks'!T3) / ( (Assessments!$C$2*Assessments!$B$2) + (Assessments!$C$3*Assessments!$B$3) + (Assessments!$C$4*Assessments!$B$4) + (Assessments!$C$5*Assessments!$B$5) + (Assessments!$C$6*Assessments!$B$6)) * 100 -> 81.607843 | D2: =IF(C2>=Assessments!$G$2*1.2, 3, IF(C2>=Assessments!$G$2, 2, 1)) -> 3 | E2: =('Componentwise marks'!E3 + 'Componentwise marks'!I3 + 'Componentwise marks'!M3 + 'Componentwise marks'!Q3 + 'Componentwise marks'!U3) / ( (Assessments!$D$2*Assessments!$B$2) + (Assessments!$D$3*Assessments!$B$3) + (Assessments!$D$4*Assessments!$B$4) + (Assessments!$D$5*Assessments!$B$5) + (Assessments!$D$6*Assessments!$B$6)) * 100 -> 81.093333 | F2: =IF(E2>=Assessments!$G$2*1.2, 3, IF(E2>=Assessments!$G$2, 2, 1)) -> 3 | G2: =('Componentwise marks'!F3 + 'Componentwise marks'!J3 + 'Componentwise marks'!N3 + 'Componentwise marks'!R3 + 'Componentwise marks'!V3) / ( (Assessments!$E$2*Assessments!$B$2) + (Assessments!$E$3*Assessments!$B$3) + (Assessments!$E$4*Assessments!$B$4) + (Assessments!$E$5*Assessments!$B$5) + (Assessments!$E$6*Assessments!$B$6)) * 100 -> 79.405405 | H2: =IF(G2>=Assessments!$G$2*1.2, 3, IF(G2>=Assessments!$G$2, 2, 1)) -> 3 | I2: =('Componentwise marks'!G3 + 'Componentwise marks'!K3 + 'Componentwise marks'!O3 + 'Componentwise marks'!S3 + 'Componentwise marks'!W3) / ( (Assessments!$F$2*Assessments!$B$2) + (Assessments!$F$3*Assessments!$B$3) + (Assessments!$F$4*Assessments!$B$4) + (Assessments!$F$5*Assessments!$B$5) + (Assessments!$F$6*Assessments!$B$6)) * 100 -> 79.405405 | J2: =IF(I2>=Assessments!$G$2*1.2, 3, IF(I2>=Assessments!$G$2, 2, 1)) -> 3 | K2: =C2*0.9 -> 73.447059 | L2: =C2*0.05 -> 4.0803922 | M2: =C2*0.05 -> 4.0803922 | N2: =E2*0.7 -> 56.765333 | O2: =E2*0.15 -> 12.164 | P2: =E2*0.15 -> 12.164 | Q2: =G2*0.4 -> 31.762162 | R2: =G2*0.5 -> 39.702703 | S2: =G2*0.1 -> 7.9405405 | T2: =I2*0.4 -> 31.762162 | U2: =I2*0.5 -> 39.702703 | V2: =I2*0.1 -> 7.9405405 | W2: =(K2+N2+Q2+T2)/(0.9+0.7+0.4+0.4) -> 80.723632 | X2: =IF(W2>=Assessments!$G$2*1.2, 3, IF(W2>=Assessments!$G$2, 2, 1)) -> 3 | Y2: =(L2+O2+R2+U2)/(0.05+0.15+0.5+0.5) -> 79.708165 | Z2: =IF(Y2>=Assessments!$G$2*1.2, 3, IF(Y2>=Assessments!$G$2, 2, 1)) -> 3 | AA2: =(M2+P2+S2+V2)/(0.05+0.15+0.1+0.1) -> 80.313683 | AB2: =IF(AA2>=Assessments!$G$2*1.2, 3, IF(AA2>=Assessments!$G$2, 2, 1)) -> 3 | AC2: =((COs!$E$2 * C2 + COs!$E$3 * E2 + COs!$E$4 * G2 + COs!$E$5 * I2) / (COs!$E$2 * Assessments!$B$2 * Assessments!$C$2 + COs!$E$3 * Assessments!$B$3 * Assessments!$D$3 + COs!$E$4 * Assessments!$B$4 * Assessments!$E$4 + COs!$E$5 * Assessments!$B$5 * Assessments!$F$5)) -> 65.121631 | AD2: =IF(AC2>=Assessments!$G$2*1.2, 3, IF(AC2>=Assessments!$G$2, 2, 1)) -> 2 | AE2: =((COs!$E$2 * C2 + COs!$E$3 * E2 + COs!$E$4 * G2 + COs!$E$5 * I2) / (COs!$E$2 * Assessments!$B$2 * Assessments!$C$2 + COs!$E$3 * Assessments!$B$3 * Assessments!$D$3 + COs!$E$4 * Assessments!$B$4 * Assessments!$E$4 + COs!$E$5 * Assessments!$B$5 * Assessments!$F$5)) -> 65.121631 | AF2: =IF(AE2>=Assessments!$G$2*1.2, 3, IF(AE2>=Assessments!$G$2, 2, 1)) -> 2 | AG2: =((COs!$G$2 * C2 + COs!$G$3 * E2 + COs!$G$4 * G2 + COs!$G$5 * I2) / (COs!$G$2 * Assessments!$B$2 * Assessments!$C$2 + COs!$G$3 * Assessments!$B$3 * Assessments!$D$3 + COs!$G$4 * Assessments!$B$4 * Assessments!$E$4 + COs!$G$5 * Assessments!$B$5 * Assessments!$F$5)) -> 61.463887 | AH2: =IF(AG2>=Assessments!$G$2*1.2, 3, IF(AG2>=Assessments!$G$2, 2, 1)) -> 1 | AI2: =((COs!$H$2 * C2 + COs!$H$3 * E2 + COs!$H$4 * G2 + COs!$H$5 * I2) / (COs!$H$2 * Assessments!$B$2 * Assessments!$C$2 + COs!$H$3 * Assessments!$B$3 * Assessments!$D$3 + COs!$H$4 * Assessments!$B$4 * Assessments!$E$4 + COs!$H$5 * Assessments!$B$5 * Assessments!$F$5)) -> 36.551321 | AJ2: =IF(AI2>=Assessments!$G$2*1.2, 3, IF(AI2>=Assessments!$G$2, 2, 1)) -> 1 | AK2: =((COs!$I$2 * C2 + COs!$I$3 * E2 + COs!$I$4 * G2 + COs!$I$5 * I2) / (COs!$I$2 * Assessments!$B$2 * Assessments!$C$2 + COs!$I$3 * Assessments!$B$3 * Assessments!$D$3 + COs!$I$4 * Assessments!$B$4 * Assessments!$E$4 + COs!$I$5 * Assessments!$B$5 * Assessments!$F$5)) -> 65.011869 | AL2: =IF(AK2>=Assessments!$G$2*1.2, 3, IF(AK2>=Assessments!$G$2, 2, 1)) -> 2 | AM2: =((COs!$J$2 * C2 + COs!$J$3 * E2 + COs!$J$4 * G2 + COs!$J$5 * I2) / (COs!$J$2 * Assessments!$B$2 * Assessments!$C$2 + COs!$J$3 * Assessments!$B$3 * Assessments!$D$3 + COs!$J$4 * Assessments!$B$4 * Assessments!$E$4 + COs!$J$5 * Assessments!$B$5 * Assessments!$F$5)) -> 26.468468 | AN2: =IF(AM2>=Assessments!$G$2*1.2, 3, IF(AM2>=Assessments!$G$2, 2, 1)) -> 1 | AO2: =((COs!$K$2 * C2 + COs!$K$3 * E2 + COs!$K$4 * G2 + COs!$K$5 * I2) / (COs!$K$2 * Assessments!$B$2 * Assessments!$C$2 + COs!$K$3 * Assessments!$B$3 * Assessments!$D$3 + COs!$K$4 * Assessments!$B$4 * Assessments!$E$4 + COs!$K$5 * Assessments!$B$5 * Assessments!$F$5)) -> 26.468468 | AP2: =IF(AO2>=Assessments!$G$2*1.2, 3, IF(AO2>=Assessments!$G$2, 2, 1)) -> 1 | AQ2: =((COs!$L$2 * C2 + COs!$L$3 * E2 + COs!$L$4 * G2 + COs!$L$5 * I2) / (COs!$L$2 * Assessments!$B$2 * Assessments!$C$2 + COs!$L$3 * Assessments!$B$3 * Assessments!$D$3 + COs!$L$4 * Assessments!$B$4 * Assessments!$E$4 + COs!$L$5 * Assessments!$B$5 * Assessments!$F$5)) -> 35.291291 | AR2: =IF(AQ2>=Assessments!$G$2*1.2, 3, IF(AQ2>=Assessments!$G$2, 2, 1)) -> 1 | AS2: =((COs!$M$2 * C2 + COs!$M$3 * E2 + COs!$M$4 * G2 + COs!$M$5 * I2) / (COs!$M$2 * Assessments!$B$2 * Assessments!$C$2 + COs!$M$3 * Assessments!$B$3 * Assessments!$D$3 + COs!$M$4 * Assessments!$B$4 * Assessments!$E$4 + COs!$M$5 * Assessments!$B$5 * Assessments!$F$5)) -> 35.291291 | AT2: =IF(AS2>=Assessments!$G$2*1.2, 3, IF(AS2>=Assessments!$G$2, 2, 1)) -> 1 | AU2: =((COs!$N$2 * C2 + COs!$N$3 * E2 + COs!$N$4 * G2 + COs!$N$5 * I2) / (COs!$N$2 * Assessments!$B$2 * Assessments!$C$2 + COs!$N$3 * Assessments!$B$3 * Assessments!$D$3 + COs!$N$4 * Assessments!$B$4 * Assessments!$E$4 + COs!$N$5 * Assessments!$B$5 * Assessments!$F$5)) -> 49.489768 | AV2: =IF(AU2>=Assessments!$G$2*1.2, 3, IF(AU2>=Assessments!$G$2, 2, 1)) -> 1 | AW2: =((COs!$O$2 * C2 + COs!$O$3 * E2 + COs!$O$4 * G2 + COs!$O$5 * I2) / (COs!$O$2 * Assessments!$B$2 * Assessments!$C$2 + COs!$O$3 * Assessments!$B$3 * Assessments!$D$3 + COs!$O$4 * Assessments!$B$4 * Assessments!$E$4 + COs!$O$5 * Assessments!$B$5 * Assessments!$F$5)) -> 36.084555 | AX2: =IF(AW2>=Assessments!$G$2*1.2, 3, IF(AW2>=Assessments!$G$2, 2, 1)) -> 1 | AY2: =((COs!$P$2 * C2 + COs!$P$3 * E2 + COs!$P$4 * G2 + COs!$P$5 * I2) / (COs!$P$2 * Assessments!$B$2 * Assessments!$C$2 + COs!$P$3 * Assessments!$B$3 * Assessments!$D$3 + COs!$P$4 * Assessments!$B$4 * Assessments!$E$4 + COs!$P$5 * Assessments!$B$5 * Assessments!$F$5)) -> 31.762162 | AZ2: =IF(AY2>=Assessments!$G$2*1.2, 3, IF(AY2>=Assessments!$G$2, 2, 1)) -> 1
A3: ='IA Marks'!B4 -> 22BSR16005 | B3: ='IA Marks'!C4 -> MANYA MAHESHWARI | C3: =('Componentwise marks'!D4 + 'Componentwise marks'!H4 + 'Componentwise marks'!L4 + 'Componentwise marks'!P4 + 'Componentwise marks'!T4) / ( (Assessments!$C$2*Assessments!$B$2) + (Assessments!$C$3*Assessments!$B$3) + (Assessments!$C$4*Assessments!$B$4) + (Assessments!$C$5*Assessments!$B$5) + (Assessments!$C$6*Assessments!$B$6)) * 100 -> 81.470588 | D3: =IF(C3>=Assessments!$G$2*1.2, 3, IF(C3>=Assessments!$G$2, 2, 1)) -> 3 | E3: =('Componentwise marks'!E4 + 'Componentwise marks'!I4 + 'Componentwise marks'!M4 + 'Componentwise marks'!Q4 + 'Componentwise marks'!U4) / ( (Assessments!$D$2*Assessments!$B$2) + (Assessments!$D$3*Assessments!$B$3) + (Assessments!$D$4*Assessments!$B$4) + (Assessments!$D$5*Assessments!$B$5) + (Assessments!$D$6*Assessments!$B$6)) * 100 -> 81 | F3: =IF(E3>=Assessments!$G$2*1.2, 3, IF(E3>=Assessments!$G$2, 2, 1)) -> 3 | G3: =('Componentwise marks'!F4 + 'Componentwise marks'!J4 + 'Componentwise marks'!N4 + 'Componentwise marks'!R4 + 'Componentwise marks'!V4) / ( (Assessments!$E$2*Assessments!$B$2) + (Assessments!$E$3*Assessments!$B$3) + (Assessments!$E$4*Assessments!$B$4) + (Assessments!$E$5*Assessments!$B$5) + (Assessments!$E$6*Assessments!$B$6)) * 100 -> 79.324324 | H3: =IF(G3>=Assessments!$G$2*1.2, 3, IF(G3>=Assessments!$G$2, 2, 1)) -> 3 | I3: =('Componentwise marks'!G4 + 'Componentwise marks'!K4 + 'Componentwise marks'!O4 + 'Componentwise marks'!S4 + 'Componentwise marks'!W4) / ( (Assessments!$F$2*Assessments!$B$2) + (Assessments!$F$3*Assessments!$B$3) + (Assessments!$F$4*Assessments!$B$4) + (Assessments!$F$5*Assessments!$B$5) + (Assessments!$F$6*Assessments!$B$6)) * 100 -> 79.324324 | J3: =IF(I3>=Assessments!$G$2*1.2, 3, IF(I3>=Assessments!$G$2, 2, 1)) -> 3 | K3: =C3*0.9 -> 73.323529 | L3: =C3*0.05 -> 4.0735294 | M3: =C3*0.05 -> 4.0735294 | N3: =E3*0.7 -> 56.7 | O3: =E3*0.15 -> 12.15 | P3: =E3*0.15 -> 12.15 | Q3: =G3*0.4 -> 31.72973 | R3: =G3*0.5 -> 39.662162 | S3: =G3*0.1 -> 7.9324324 | T3: =I3*0.4 -> 31.72973 | U3: =I3*0.5 -> 39.662162 | V3: =I3*0.1 -> 7.9324324 | W3: =(K3+N3+Q3+T3)/(0.9+0.7+0.4+0.4) -> 80.617912 | X3: =IF(W3>=Assessments!$G$2*1.2, 3, IF(W3>=Assessments!$G$2, 2, 1)) -> 3 | Y3: =(L3+O3+R3+U3)/(0.05+0.15+0.5+0.5) -> 79.623211 | Z3: =IF(Y3>=Assessments!$G$2*1.2, 3, IF(Y3>=Assessments!$G$2, 2, 1)) -> 3 | AA3: =(M3+P3+S3+V3)/(0.05+0.15+0.1+0.1) -> 80.220986 | AB3: =IF(AA3>=Assessments!$G$2*1.2, 3, IF(AA3>=Assessments!$G$2, 2, 1)) -> 3 | AC3: =((COs!$E$2 * C3 + COs!$E$3 * E3 + COs!$E$4 * G3 + COs!$E$5 * I3) / (COs!$E$2 * Assessments!$B$2 * Assessments!$C$2 + COs!$E$3 * Assessments!$B$3 * Assessments!$D$3 + COs!$E$4 * Assessments!$B$4 * Assessments!$E$4 + COs!$E$5 * Assessments!$B$5 * Assessments!$F$5)) -> 65.025882 | AD3: =IF(AC3>=Assessments!$G$2*1.2, 3, IF(AC3>=Assessments!$G$2, 2, 1)) -> 2 | AE3: =((COs!$E$2 * C3 + COs!$E$3 * E3 + COs!$E$4 * G3 + COs!$E$5 * I3) / (COs!$E$2 * Assessments!$B$2 * Assessments!$C$2 + COs!$E$3 * Assessments!$B$3 * Assessments!$D$3 + COs!$E$4 * Assessments!$B$4 * Assessments!$E$4 + COs!$E$5 * Assessments!$B$5 * Assessments!$F$5)) -> 65.025882 | AF3: =IF(AE3>=Assessments!$G$2*1.2, 3, IF(AE3>=Assessments!$G$2, 2, 1)) -> 2 | AG3: =((COs!$G$2 * C3 + COs!$G$3 * E3 + COs!$G$4 * G3 + COs!$G$5 * I3) / (COs!$G$2 * Assessments!$B$2 * Assessments!$C$2 + COs!$G$3 * Assessments!$B$3 * Assessments!$D$3 + COs!$G$4 * Assessments!$B$4 * Assessments!$E$4 + COs!$G$5 * Assessments!$B$5 * Assessments!$F$5)) -> 61.395109 | AH3: =IF(AG3>=Assessments!$G$2*1.2, 3, IF(AG3>=Assessments!$G$2, 2, 1)) -> 1 | AI3: =((COs!$H$2 * C3 + COs!$H$3 * E3 + COs!$H$4 * G3 + COs!$H$5 * I3) / (COs!$H$2 * Assessments!$B$2 * Assessments!$C$2 + COs!$H$3 * Assessments!$B$3 * Assessments!$D$3 + COs!$H$4 * Assessments!$B$4 * Assessments!$E$4 + COs!$H$5 * Assessments!$B$5 * Assessments!$F$5)) -> 36.507836 | AJ3: =IF(AI3>=Assessments!$G$2*1.2, 3, IF(AI3>=Assessments!$G$2, 2, 1)) -> 1 | AK3: =((COs!$I$2 * C3 + COs!$I$3 * E3 + COs!$I$4 * G3 + COs!$I$5 * I3) / (COs!$I$2 * Assessments!$B$2 * Assessments!$C$2 + COs!$I$3 * Assessments!$B$3 * Assessments!$D$3 + COs!$I$4 * Assessments!$B$4 * Assessments!$E$4 + COs!$I$5 * Assessments!$B$5 * Assessments!$F$5)) -> 64.92549 | AL3: =IF(AK3>=Assessments!$G$2*1.2, 3, IF(AK3>=Assessments!$G$2, 2, 1)) -> 1 | AM3: =((COs!$J$2 * C3 + COs!$J$3 * E3 + COs!$J$4 * G3 + COs!$J$5 * I3) / (COs!$J$2 * Assessments!$B$2 * Assessments!$C$2 + COs!$J$3 * Assessments!$B$3 * Assessments!$D$3 + COs!$J$4 * Assessments!$B$4 * Assessments!$E$4 + COs!$J$5 * Assessments!$B$5 * Assessments!$F$5)) -> 26.441441 | AN3: =IF(AM3>=Assessments!$G$2*1.2, 3, IF(AM3>=Assessments!$G$2, 2, 1)) -> 1 | AO3: =((COs!$K$2 * C3 + COs!$K$3 * E3 + COs!$K$4 * G3 + COs!$K$5 * I3) / (COs!$K$2 * Assessments!$B$2 * Assessments!$C$2 + COs!$K$3 * Assessments!$B$3 * Assessments!$D$3 + COs!$K$4 * Assessments!$B$4 * Assessments!$E$4 + COs!$K$5 * Assessments!$B$5 * Assessments!$F$5)) -> 26.441441 | AP3: =IF(AO3>=Assessments!$G$2*1.2, 3, IF(AO3>=Assessments!$G$2, 2, 1)) -> 1 | AQ3: =((COs!$L$2 * C3 + COs!$L$3 * E3 + COs!$L$4 * G3 + COs!$L$5 * I3) / (COs!$L$2 * Assessments!$B$2 * Assessments!$C$2 + COs!$L$3 * Assessments!$B$3 * Assessments!$D$3 + COs!$L$4 * Assessments!$B$4 * Assessments!$E$4 + COs!$L$5 * Assessments!$B$5 * Assessments!$F$5)) -> 35.255255 | AR3: =IF(AQ3>=Assessments!$G$2*1.2, 3, IF(AQ3>=Assessments!$G$2, 2, 1)) -> 1 | AS3: =((COs!$M$2 * C3 + COs!$M$3 * E3 + COs!$M$4 * G3 + COs!$M$5 * I3) / (COs!$M$2 * Assessments!$B$2 * Assessments!$C$2 + COs!$M$3 * Assessments!$B$3 * Assessments!$D$3 + COs!$M$4 * Assessments!$B$4 * Assessments!$E$4 + COs!$M$5 * Assessments!$B$5 * Assessments!$F$5)) -> 35.255255 | AT3: =IF(AS3>=Assessments!$G$2*1.2, 3, IF(AS3>=Assessments!$G$2, 2, 1)) -> 1 | AU3: =((COs!$N$2 * C3 + COs!$N$3 * E3 + COs!$N$4 * G3 + COs!$N$5 * I3) / (COs!$N$2 * Assessments!$B$2 * Assessments!$C$2 + COs!$N$3 * Assessments!$B$3 * Assessments!$D$3 + COs!$N$4 * Assessments!$B$4 * Assessments!$E$4 + COs!$N$5 * Assessments!$B$5 * Assessments!$F$5)) -> 49.427092 | AV3: =IF(AU3>=Assessments!$G$2*1.2, 3, IF(AU3>=Assessments!$G$2, 2, 1)) -> 1 | AW3: =((COs!$O$2 * C3 + COs!$O$3 * E3 + COs!$O$4 * G3 + COs!$O$5 * I3) / (COs!$O$2 * Assessments!$B$2 * Assessments!$C$2 + COs!$O$3 * Assessments!$B$3 * Assessments!$D$3 + COs!$O$4 * Assessments!$B$4 * Assessments!$E$4 + COs!$O$5 * Assessments!$B$5 * Assessments!$F$5)) -> 36.046915 | AX3: =IF(AW3>=Assessments!$G$2*1.2, 3, IF(AW3>=Assessments!$G$2, 2, 1)) -> 1 | AY3: =((COs!$P$2 * C3 + COs!$P$3 * E3 + COs!$P$4 * G3 + COs!$P$5 * I3) / (COs!$P$2 * Assessments!$B$2 * Assessments!$C$2 + COs!$P$3 * Assessments!$B$3 * Assessments!$D$3 + COs!$P$4 * Assessments!$B$4 * Assessments!$E$4 + COs!$P$5 * Assessments!$B$5 * Assessments!$F$5)) -> 31.72973 | AZ3: =IF(AY3>=Assessments!$G$2*1.2, 3, IF(AY3>=Assessments!$G$2, 2, 1)) -> 1
A4: ='IA Marks'!B5 -> 22BSR16006 | B4: ='IA Marks'!C5 -> PRERANA IYENGAR K L | C4: =('Componentwise marks'!D5 + 'Componentwise marks'!H5 + 'Componentwise marks'!L5 + 'Componentwise marks'!P5 + 'Componentwise marks'!T5) / ( (Assessments!$C$2*Assessments!$B$2) + (Assessments!$C$3*Assessments!$B$3) + (Assessments!$C$4*Assessments!$B$4) + (Assessments!$C$5*Assessments!$B$5) + (Assessments!$C$6*Assessments!$B$6)) * 100 -> 93.921569 | D4: =IF(C4>=Assessments!$G$2*1.2, 3, IF(C4>=Assessments!$G$2, 2, 1)) -> 3 | E4: =('Componentwise marks'!E5 + 'Componentwise marks'!I5 + 'Componentwise marks'!M5 + 'Componentwise marks'!Q5 + 'Componentwise marks'!U5) / ( (Assessments!$D$2*Assessments!$B$2) + (Assessments!$D$3*Assessments!$B$3) + (Assessments!$D$4*Assessments!$B$4) + (Assessments!$D$5*Assessments!$B$5) + (Assessments!$D$6*Assessments!$B$6)) * 100 -> 90.533333 | F4: =IF(E4>=Assessments!$G$2*1.2, 3, IF(E4>=Assessments!$G$2, 2, 1)) -> 3 | G4: =('Componentwise marks'!F5 + 'Componentwise marks'!J5 + 'Componentwise marks'!N5 + 'Componentwise marks'!R5 + 'Componentwise marks'!V5) / ( (Assessments!$E$2*Assessments!$B$2) + (Assessments!$E$3*Assessments!$B$3) + (Assessments!$E$4*Assessments!$B$4) + (Assessments!$E$5*Assessments!$B$5) + (Assessments!$E$6*Assessments!$B$6)) * 100 -> 92.162162 | H4: =IF(G4>=Assessments!$G$2*1.2, 3, IF(G4>=Assessments!$G$2, 2, 1)) -> 3 | I4: =('Componentwise marks'!G5 + 'Componentwise marks'!K5 + 'Componentwise marks'!O5 + 'Componentwise marks'!S5 + 'Componentwise marks'!W5) / ( (Assessments!$F$2*Assessments!$B$2) + (Assessments!$F$3*Assessments!$B$3) + (Assessments!$F$4*Assessments!$B$4) + (Assessments!$F$5*Assessments!$B$5) + (Assessments!$F$6*Assessments!$B$6)) * 100 -> 92.162162 | J4: =IF(I4>=Assessments!$G$2*1.2, 3, IF(I4>=Assessments!$G$2, 2, 1)) -> 3 | K4: =C4*0.9 -> 84.529412 | L4: =C4*0.05 -> 4.6960784 | M4: =C4*0.05 -> 4.6960784 | N4: =E4*0.7 -> 63.373333 | O4: =E4*0.15 -> 13.58 | P4: =E4*0.15 -> 13.58 | Q4: =G4*0.4 -> 36.864865 | R4: =G4*0.5 -> 46.081081 | S4: =G4*0.1 -> 9.2162162 | T4: =I4*0.4 -> 36.864865 | U4: =I4*0.5 -> 46.081081 | V4: =I4*0.1 -> 9.2162162 | W4: =(K4+N4+Q4+T4)/(0.9+0.7+0.4+0.4) -> 92.346865 | X4: =IF(W4>=Assessments!$G$2*1.2, 3, IF(W4>=Assessments!$G$2, 2, 1)) -> 3 | Y4: =(L4+O4+R4+U4)/(0.05+0.15+0.5+0.5) -> 92.031867 | Z4: =IF(Y4>=Assessments!$G$2*1.2, 3, IF(Y4>=Assessments!$G$2, 2, 1)) -> 3 | AA4: =(M4+P4+S4+V4)/(0.05+0.15+0.1+0.1) -> 91.771277 | AB4: =IF(AA4>=Assessments!$G$2*1.2, 3, IF(AA4>=Assessments!$G$2, 2, 1)) -> 3 | AC4: =((COs!$E$2 * C4 + COs!$E$3 * E4 + COs!$E$4 * G4 + COs!$E$5 * I4) / (COs!$E$2 * Assessments!$B$2 * Assessments!$C$2 + COs!$E$3 * Assessments!$B$3 * Assessments!$D$3 + COs!$E$4 * Assessments!$B$4 * Assessments!$E$4 + COs!$E$5 * Assessments!$B$5 * Assessments!$F$5)) -> 74.05302 | AD4: =IF(AC4>=Assessments!$G$2*1.2, 3, IF(AC4>=Assessments!$G$2, 2, 1)) -> 2 | AE4: =((COs!$E$2 * C4 + COs!$E$3 * E4 + COs!$E$4 * G4 + COs!$E$5 * I4) / (COs!$E$2 * Assessments!$B$2 * Assessments!$C$2 + COs!$E$3 * Assessments!$B$3 * Assessments!$D$3 + COs!$E$4 * Assessments!$B$4 * Assessments!$E$4 + COs!$E$5 * Assessments!$B$5 * Assessments!$F$5)) -> 74.05302 | AF4: =IF(AE4>=Assessments!$G$2*1.2, 3, IF(AE4>=Assessments!$G$2, 2, 1)) -> 2 | AG4: =((COs!$G$2 * C4 + COs!$G$3 * E4 + COs!$G$4 * G4 + COs!$G$5 * I4) / (COs!$G$2 * Assessments!$B$2 * Assessments!$C$2 + COs!$G$3 * Assessments!$B$3 * Assessments!$D$3 + COs!$G$4 * Assessments!$B$4 * Assessments!$E$4 + COs!$G$5 * Assessments!$B$5 * Assessments!$F$5)) -> 69.288031 | AH4: =IF(AG4>=Assessments!$G$2*1.2, 3, IF(AG4>=Assessments!$G$2, 2, 1)) -> 2 | AI4: =((COs!$H$2 * C4 + COs!$H$3 * E4 + COs!$H$4 * G4 + COs!$H$5 * I4) / (COs!$H$2 * Assessments!$B$2 * Assessments!$C$2 + COs!$H$3 * Assessments!$B$3 * Assessments!$D$3 + COs!$H$4 * Assessments!$B$4 * Assessments!$E$4 + COs!$H$5 * Assessments!$B$5 * Assessments!$F$5)) -> 42.332349 | AJ4: =IF(AI4>=Assessments!$G$2*1.2, 3, IF(AI4>=Assessments!$G$2, 2, 1)) -> 1 | AK4: =((COs!$I$2 * C4 + COs!$I$3 * E4 + COs!$I$4 * G4 + COs!$I$5 * I4) / (COs!$I$2 * Assessments!$B$2 * Assessments!$C$2 + COs!$I$3 * Assessments!$B$3 * Assessments!$D$3 + COs!$I$4 * Assessments!$B$4 * Assessments!$E$4 + COs!$I$5 * Assessments!$B$5 * Assessments!$F$5)) -> 73.330196 | AL4: =IF(AK4>=Assessments!$G$2*1.2, 3, IF(AK4>=Assessments!$G$2, 2, 1)) -> 2 | AM4: =((COs!$J$2 * C4 + COs!$J$3 * E4 + COs!$J$4 * G4 + COs!$J$5 * I4) / (COs!$J$2 * Assessments!$B$2 * Assessments!$C$2 + COs!$J$3 * Assessments!$B$3 * Assessments!$D$3 + COs!$J$4 * Assessments!$B$4 * Assessments!$E$4 + COs!$J$5 * Assessments!$B$5 * Assessments!$F$5)) -> 30.720721 | AN4: =IF(AM4>=Assessments!$G$2*1.2, 3, IF(AM4>=Assessments!$G$2, 2, 1)) -> 1 | AO4: =((COs!$K$2 * C4 + COs!$K$3 * E4 + COs!$K$4 * G4 + COs!$K$5 * I4) / (COs!$K$2 * Assessments!$B$2 * Assessments!$C$2 + COs!$K$3 * Assessments!$B$3 * Assessments!$D$3 + COs!$K$4 * Assessments!$B$4 * Assessments!$E$4 + COs!$K$5 * Assessments!$B$5 * Assessments!$F$5)) -> 30.720721 | AP4: =IF(AO4>=Assessments!$G$2*1.2, 3, IF(AO4>=Assessments!$G$2, 2, 1)) -> 1 | AQ4: =((COs!$L$2 * C4 + COs!$L$3 * E4 + COs!$L$4 * G4 + COs!$L$5 * I4) / (COs!$L$2 * Assessments!$B$2 * Assessments!$C$2 + COs!$L$3 * Assessments!$B$3 * Assessments!$D$3 + COs!$L$4 * Assessments!$B$4 * Assessments!$E$4 + COs!$L$5 * Assessments!$B$5 * Assessments!$F$5)) -> 40.960961 | AR4: =IF(AQ4>=Assessments!$G$2*1.2, 3, IF(AQ4>=Assessments!$G$2, 2, 1)) -> 1 | AS4: =((COs!$M$2 * C4 + COs!$M$3 * E4 + COs!$M$4 * G4 + COs!$M$5 * I4) / (COs!$M$2 * Assessments!$B$2 * Assessments!$C$2 + COs!$M$3 * Assessments!$B$3 * Assessments!$D$3 + COs!$M$4 * Assessments!$B$4 * Assessments!$E$4 + COs!$M$5 * Assessments!$B$5 * Assessments!$F$5)) -> 40.960961 | AT4: =IF(AS4>=Assessments!$G$2*1.2, 3, IF(AS4>=Assessments!$G$2, 2, 1)) -> 1 | AU4: =((COs!$N$2 * C4 + COs!$N$3 * E4 + COs!$N$4 * G4 + COs!$N$5 * I4) / (COs!$N$2 * Assessments!$B$2 * Assessments!$C$2 + COs!$N$3 * Assessments!$B$3 * Assessments!$D$3 + COs!$N$4 * Assessments!$B$4 * Assessments!$E$4 + COs!$N$5 * Assessments!$B$5 * Assessments!$F$5)) -> 56.909021 | AV4: =IF(AU4>=Assessments!$G$2*1.2, 3, IF(AU4>=Assessments!$G$2, 2, 1)) -> 1 | AW4: =((COs!$O$2 * C4 + COs!$O$3 * E4 + COs!$O$4 * G4 + COs!$O$5 * I4) / (COs!$O$2 * Assessments!$B$2 * Assessments!$C$2 + COs!$O$3 * Assessments!$B$3 * Assessments!$D$3 + COs!$O$4 * Assessments!$B$4 * Assessments!$E$4 + COs!$O$5 * Assessments!$B$5 * Assessments!$F$5)) -> 41.610879 | AX4: =IF(AW4>=Assessments!$G$2*1.2, 3, IF(AW4>=Assessments!$G$2, 2, 1)) -> 1 | AY4: =((COs!$P$2 * C4 + COs!$P$3 * E4 + COs!$P$4 * G4 + COs!$P$5 * I4) / (COs!$P$2 * Assessments!$B$2 * Assessments!$C$2 + COs!$P$3 * Assessments!$B$3 * Assessments!$D$3 + COs!$P$4 * Assessments!$B$4 * Assessments!$E$4 + COs!$P$5 * Assessments!$B$5 * Assessments!$F$5)) -> 36.864865 | AZ4: =IF(AY4>=Assessments!$G$2*1.2, 3, IF(AY4>=Assessments!$G$2, 2, 1)) -> 1
A5: ='IA Marks'!B6 -> 22BSR16025 | B5: ='IA Marks'!C6 -> DHARANESHWAR G | C5: =('Componentwise marks'!D6 + 'Componentwise marks'!H6 + 'Componentwise marks'!L6 + 'Componentwise marks'!P6 + 'Componentwise marks'!T6) / ( (Assessments!$C$2*Assessments!$B$2) + (Assessments!$C$3*Assessments!$B$3) + (Assessments!$C$4*Assessments!$B$4) + (Assessments!$C$5*Assessments!$B$5) + (Assessments!$C$6*Assessments!$B$6)) * 100 -> 79.078431 | D5: =IF(C5>=Assessments!$G$2*1.2, 3, IF(C5>=Assessments!$G$2, 2, 1)) -> 3 | E5: =('Componentwise marks'!E6 + 'Componentwise marks'!I6 + 'Componentwise marks'!M6 + 'Componentwise marks'!Q6 + 'Componentwise marks'!U6) / ( (Assessments!$D$2*Assessments!$B$2) + (Assessments!$D$3*Assessments!$B$3) + (Assessments!$D$4*Assessments!$B$4) + (Assessments!$D$5*Assessments!$B$5) + (Assessments!$D$6*Assessments!$B$6)) * 100 -> 76.173333 | F5: =IF(E5>=Assessments!$G$2*1.2, 3, IF(E5>=Assessments!$G$2, 2, 1)) -> 2 | G5: =('Componentwise marks'!F6 + 'Componentwise marks'!J6 + 'Componentwise marks'!N6 + 'Componentwise marks'!R6 + 'Componentwise marks'!V6) / ( (Assessments!$E$2*Assessments!$B$2) + (Assessments!$E$3*Assessments!$B$3) + (Assessments!$E$4*Assessments!$B$4) + (Assessments!$E$5*Assessments!$B$5) + (Assessments!$E$6*Assessments!$B$6)) * 100 -> 76.135135 | H5: =IF(G5>=Assessments!$G$2*1.2, 3, IF(G5>=Assessments!$G$2, 2, 1)) -> 2 | I5: =('Componentwise marks'!G6 + 'Componentwise marks'!K6 + 'Componentwise marks'!O6 + 'Componentwise marks'!S6 + 'Componentwise marks'!W6) / ( (Assessments!$F$2*Assessments!$B$2) + (Assessments!$F$3*Assessments!$B$3) + (Assessments!$F$4*Assessments!$B$4) + (Assessments!$F$5*Assessments!$B$5) + (Assessments!$F$6*Assessments!$B$6)) * 100 -> 76.135135 | J5: =IF(I5>=Assessments!$G$2*1.2, 3, IF(I5>=Assessments!$G$2, 2, 1)) -> 2 | K5: =C5*0.9 -> 71.170588 | L5: =C5*0.05 -> 3.9539216 | M5: =C5*0.05 -> 3.9539216 | N5: =E5*0.7 -> 53.321333 | O5: =E5*0.15 -> 11.426 | P5: =E5*0.15 -> 11.426 | Q5: =G5*0.4 -> 30.454054 | R5: =G5*0.5 -> 38.067568 | S5: =G5*0.1 -> 7.6135135 | T5: =I5*0.4 -> 30.454054 | U5: =I5*0.5 -> 38.067568 | V5: =I5*0.1 -> 7.6135135 | W5: =(K5+N5+Q5+T5)/(0.9+0.7+0.4+0.4) -> 77.250012 | X5: =IF(W5>=Assessments!$G$2*1.2, 3, IF(W5>=Assessments!$G$2, 2, 1)) -> 2 | Y5: =(L5+O5+R5+U5)/(0.05+0.15+0.5+0.5) -> 76.262547 | Z5: =IF(Y5>=Assessments!$G$2*1.2, 3, IF(Y5>=Assessments!$G$2, 2, 1)) -> 2 | AA5: =(M5+P5+S5+V5)/(0.05+0.15+0.1+0.1) -> 76.517371 | AB5: =IF(AA5>=Assessments!$G$2*1.2, 3, IF(AA5>=Assessments!$G$2, 2, 1)) -> 2 | AC5: =((COs!$E$2 * C5 + COs!$E$3 * E5 + COs!$E$4 * G5 + COs!$E$5 * I5) / (COs!$E$2 * Assessments!$B$2 * Assessments!$C$2 + COs!$E$3 * Assessments!$B$3 * Assessments!$D$3 + COs!$E$4 * Assessments!$B$4 * Assessments!$E$4 + COs!$E$5 * Assessments!$B$5 * Assessments!$F$5)) -> 62.333114 | AD5: =IF(AC5>=Assessments!$G$2*1.2, 3, IF(AC5>=Assessments!$G$2, 2, 1)) -> 1 | AE5: =((COs!$E$2 * C5 + COs!$E$3 * E5 + COs!$E$4 * G5 + COs!$E$5 * I5) / (COs!$E$2 * Assessments!$B$2 * Assessments!$C$2 + COs!$E$3 * Assessments!$B$3 * Assessments!$D$3 + COs!$E$4 * Assessments!$B$4 * Assessments!$E$4 + COs!$E$5 * Assessments!$B$5 * Assessments!$F$5)) -> 62.333114 | AF5: =IF(AE5>=Assessments!$G$2*1.2, 3, IF(AE5>=Assessments!$G$2, 2, 1)) -> 1 | AG5: =((COs!$G$2 * C5 + COs!$G$3 * E5 + COs!$G$4 * G5 + COs!$G$5 * I5) / (COs!$G$2 * Assessments!$B$2 * Assessments!$C$2 + COs!$G$3 * Assessments!$B$3 * Assessments!$D$3 + COs!$G$4 * Assessments!$B$4 * Assessments!$E$4 + COs!$G$5 * Assessments!$B$5 * Assessments!$F$5)) -> 58.02955 | AH5: =IF(AG5>=Assessments!$G$2*1.2, 3, IF(AG5>=Assessments!$G$2, 2, 1)) -> 1 | AI5: =((COs!$H$2 * C5 + COs!$H$3 * E5 + COs!$H$4 * G5 + COs!$H$5 * I5) / (COs!$H$2 * Assessments!$B$2 * Assessments!$C$2 + COs!$H$3 * Assessments!$B$3 * Assessments!$D$3 + COs!$H$4 * Assessments!$B$4 * Assessments!$E$4 + COs!$H$5 * Assessments!$B$5 * Assessments!$F$5)) -> 35.14101 | AJ5: =IF(AI5>=Assessments!$G$2*1.2, 3, IF(AI5>=Assessments!$G$2, 2, 1)) -> 1 | AK5: =((COs!$I$2 * C5 + COs!$I$3 * E5 + COs!$I$4 * G5 + COs!$I$5 * I5) / (COs!$I$2 * Assessments!$B$2 * Assessments!$C$2 + COs!$I$3 * Assessments!$B$3 * Assessments!$D$3 + COs!$I$4 * Assessments!$B$4 * Assessments!$E$4 + COs!$I$5 * Assessments!$B$5 * Assessments!$F$5)) -> 61.713359 | AL5: =IF(AK5>=Assessments!$G$2*1.2, 3, IF(AK5>=Assessments!$G$2, 2, 1)) -> 1 | AM5: =((COs!$J$2 * C5 + COs!$J$3 * E5 + COs!$J$4 * G5 + COs!$J$5 * I5) / (COs!$J$2 * Assessments!$B$2 * Assessments!$C$2 + COs!$J$3 * Assessments!$B$3 * Assessments!$D$3 + COs!$J$4 * Assessments!$B$4 * Assessments!$E$4 + COs!$J$5 * Assessments!$B$5 * Assessments!$F$5)) -> 25.378378 | AN5: =IF(AM5>=Assessments!$G$2*1.2, 3, IF(AM5>=Assessments!$G$2, 2, 1)) -> 1 | AO5: =((COs!$K$2 * C5 + COs!$K$3 * E5 + COs!$K$4 * G5 + COs!$K$5 * I5) / (COs!$K$2 * Assessments!$B$2 * Assessments!$C$2 + COs!$K$3 * Assessments!$B$3 * Assessments!$D$3 + COs!$K$4 * Assessments!$B$4 * Assessments!$E$4 + COs!$K$5 * Assessments!$B$5 * Assessments!$F$5)) -> 25.378378 | AP5: =IF(AO5>=Assessments!$G$2*1.2, 3, IF(AO5>=Assessments!$G$2, 2, 1)) -> 1 | AQ5: =((COs!$L$2 * C5 + COs!$L$3 * E5 + COs!$L$4 * G5 + COs!$L$5 * I5) / (COs!$L$2 * Assessments!$B$2 * Assessments!$C$2 + COs!$L$3 * Assessments!$B$3 * Assessments!$D$3 + COs!$L$4 * Assessments!$B$4 * Assessments!$E$4 + COs!$L$5 * Assessments!$B$5 * Assessments!$F$5)) -> 33.837838 | AR5: =IF(AQ5>=Assessments!$G$2*1.2, 3, IF(AQ5>=Assessments!$G$2, 2, 1)) -> 1 | AS5: =((COs!$M$2 * C5 + COs!$M$3 * E5 + COs!$M$4 * G5 + COs!$M$5 * I5) / (COs!$M$2 * Assessments!$B$2 * Assessments!$C$2 + COs!$M$3 * Assessments!$B$3 * Assessments!$D$3 + COs!$M$4 * Assessments!$B$4 * Assessments!$E$4 + COs!$M$5 * Assessments!$B$5 * Assessments!$F$5)) -> 33.837838 | AT5: =IF(AS5>=Assessments!$G$2*1.2, 3, IF(AS5>=Assessments!$G$2, 2, 1)) -> 1 | AU5: =((COs!$N$2 * C5 + COs!$N$3 * E5 + COs!$N$4 * G5 + COs!$N$5 * I5) / (COs!$N$2 * Assessments!$B$2 * Assessments!$C$2 + COs!$N$3 * Assessments!$B$3 * Assessments!$D$3 + COs!$N$4 * Assessments!$B$4 * Assessments!$E$4 + COs!$N$5 * Assessments!$B$5 * Assessments!$F$5)) -> 47.460062 | AV5: =IF(AU5>=Assessments!$G$2*1.2, 3, IF(AU5>=Assessments!$G$2, 2, 1)) -> 1 | AW5: =((COs!$O$2 * C5 + COs!$O$3 * E5 + COs!$O$4 * G5 + COs!$O$5 * I5) / (COs!$O$2 * Assessments!$B$2 * Assessments!$C$2 + COs!$O$3 * Assessments!$B$3 * Assessments!$D$3 + COs!$O$4 * Assessments!$B$4 * Assessments!$E$4 + COs!$O$5 * Assessments!$B$5 * Assessments!$F$5)) -> 34.47917 | AX5: =IF(AW5>=Assessments!$G$2*1.2, 3, IF(AW5>=Assessments!$G$2, 2, 1)) -> 1 | AY5: =((COs!$P$2 * C5 + COs!$P$3 * E5 + COs!$P$4 * G5 + COs!$P$5 * I5) / (COs!$P$2 * Assessments!$B$2 * Assessments!$C$2 + COs!$P$3 * Assessments!$B$3 * Assessments!$D$3 + COs!$P$4 * Assessments!$B$4 * Assessments!$E$4 + COs!$P$5 * Assessments!$B$5 * Assessments!$F$5)) -> 30.454054 | AZ5: =IF(AY5>=Assessments!$G$2*1.2, 3, IF(AY5>=Assessments!$G$2, 2, 1)) -> 1
A6: ='IA Marks'!B7 -> 22BSR16028 | B6: ='IA Marks'!C7 -> ARDRA R | C6: =('Componentwise marks'!D7 + 'Componentwise marks'!H7 + 'Componentwise marks'!L7 + 'Componentwise marks'!P7 + 'Componentwise marks'!T7) / ( (Assessments!$C$2*Assessments!$B$2) + (Assessments!$C$3*Assessments!$B$3) + (Assessments!$C$4*Assessments!$B$4) + (Assessments!$C$5*Assessments!$B$5) + (Assessments!$C$6*Assessments!$B$6)) * 100 -> 84.745098 | D6: =IF(C6>=Assessments!$G$2*1.2, 3, IF(C6>=Assessments!$G$2, 2, 1)) -> 3 | E6: =('Componentwise marks'!E7 + 'Componentwise marks'!I7 + 'Componentwise marks'!M7 + 'Componentwise marks'!Q7 + 'Componentwise marks'!U7) / ( (Assessments!$D$2*Assessments!$B$2) + (Assessments!$D$3*Assessments!$B$3) + (Assessments!$D$4*Assessments!$B$4) + (Assessments!$D$5*Assessments!$B$5) + (Assessments!$D$6*Assessments!$B$6)) * 100 -> 82.16 | F6: =IF(E6>=Assessments!$G$2*1.2, 3, IF(E6>=Assessments!$G$2, 2, 1)) -> 3 | G6: =('Componentwise marks'!F7 + 'Componentwise marks'!J7 + 'Componentwise marks'!N7 + 'Componentwise marks'!R7 + 'Componentwise marks'!V7) / ( (Assessments!$E$2*Assessments!$B$2) + (Assessments!$E$3*Assessments!$B$3) + (Assessments!$E$4*Assessments!$B$4) + (Assessments!$E$5*Assessments!$B$5) + (Assessments!$E$6*Assessments!$B$6)) * 100 -> 84.27027 | H6: =IF(G6>=Assessments!$G$2*1.2, 3, IF(G6>=Assessments!$G$2, 2, 1)) -> 3 | I6: =('Componentwise marks'!G7 + 'Componentwise marks'!K7 + 'Componentwise marks'!O7 + 'Componentwise marks'!S7 + 'Componentwise marks'!W7) / ( (Assessments!$F$2*Assessments!$B$2) + (Assessments!$F$3*Assessments!$B$3) + (Assessments!$F$4*Assessments!$B$4) + (Assessments!$F$5*Assessments!$B$5) + (Assessments!$F$6*Assessments!$B$6)) * 100 -> 84.27027 | J6: =IF(I6>=Assessments!$G$2*1.2, 3, IF(I6>=Assessments!$G$2, 2, 1)) -> 3 | K6: =C6*0.9 -> 76.270588 | L6: =C6*0.05 -> 4.2372549 | M6: =C6*0.05 -> 4.2372549 | N6: =E6*0.7 -> 57.512 | O6: =E6*0.15 -> 12.324 | P6: =E6*0.15 -> 12.324 | Q6: =G6*0.4 -> 33.708108 | R6: =G6*0.5 -> 42.135135 | S6: =G6*0.1 -> 8.427027 | T6: =I6*0.4 -> 33.708108 | U6: =I6*0.5 -> 42.135135 | V6: =I6*0.1 -> 8.427027 | W6: =(K6+N6+Q6+T6)/(0.9+0.7+0.4+0.4) -> 83.832835 | X6: =IF(W6>=Assessments!$G$2*1.2, 3, IF(W6>=Assessments!$G$2, 2, 1)) -> 3 | Y6: =(L6+O6+R6+U6)/(0.05+0.15+0.5+0.5) -> 84.026271 | Z6: =IF(Y6>=Assessments!$G$2*1.2, 3, IF(Y6>=Assessments!$G$2, 2, 1)) -> 3 | AA6: =(M6+P6+S6+V6)/(0.05+0.15+0.1+0.1) -> 83.538272 | AB6: =IF(AA6>=Assessments!$G$2*1.2, 3, IF(AA6>=Assessments!$G$2, 2, 1)) -> 3 | AC6: =((COs!$E$2 * C6 + COs!$E$3 * E6 + COs!$E$4 * G6 + COs!$E$5 * I6) / (COs!$E$2 * Assessments!$B$2 * Assessments!$C$2 + COs!$E$3 * Assessments!$B$3 * Assessments!$D$3 + COs!$E$4 * Assessments!$B$4 * Assessments!$E$4 + COs!$E$5 * Assessments!$B$5 * Assessments!$F$5)) -> 66.968847 | AD6: =IF(AC6>=Assessments!$G$2*1.2, 3, IF(AC6>=Assessments!$G$2, 2, 1)) -> 2 | AE6: =((COs!$E$2 * C6 + COs!$E$3 * E6 + COs!$E$4 * G6 + COs!$E$5 * I6) / (COs!$E$2 * Assessments!$B$2 * Assessments!$C$2 + COs!$E$3 * Assessments!$B$3 * Assessments!$D$3 + COs!$E$4 * Assessments!$B$4 * Assessments!$E$4 + COs!$E$5 * Assessments!$B$5 * Assessments!$F$5)) -> 66.968847 | AF6: =IF(AE6>=Assessments!$G$2*1.2, 3, IF(AE6>=Assessments!$G$2, 2, 1)) -> 2 | AG6: =((COs!$G$2 * C6 + COs!$G$3 * E6 + COs!$G$4 * G6 + COs!$G$5 * I6) / (COs!$G$2 * Assessments!$B$2 * Assessments!$C$2 + COs!$G$3 * Assessments!$B$3 * Assessments!$D$3 + COs!$G$4 * Assessments!$B$4 * Assessments!$E$4 + COs!$G$5 * Assessments!$B$5 * Assessments!$F$5)) -> 63.000051 | AH6: =IF(AG6>=Assessments!$G$2*1.2, 3, IF(AG6>=Assessments!$G$2, 2, 1)) -> 1 | AI6: =((COs!$H$2 * C6 + COs!$H$3 * E6 + COs!$H$4 * G6 + COs!$H$5 * I6) / (COs!$H$2 * Assessments!$B$2 * Assessments!$C$2 + COs!$H$3 * Assessments!$B$3 * Assessments!$D$3 + COs!$H$4 * Assessments!$B$4 * Assessments!$E$4 + COs!$H$5 * Assessments!$B$5 * Assessments!$F$5)) -> 38.577818 | AJ6: =IF(AI6>=Assessments!$G$2*1.2, 3, IF(AI6>=Assessments!$G$2, 2, 1)) -> 1 | AK6: =((COs!$I$2 * C6 + COs!$I$3 * E6 + COs!$I$4 * G6 + COs!$I$5 * I6) / (COs!$I$2 * Assessments!$B$2 * Assessments!$C$2 + COs!$I$3 * Assessments!$B$3 * Assessments!$D$3 + COs!$I$4 * Assessments!$B$4 * Assessments!$E$4 + COs!$I$5 * Assessments!$B$5 * Assessments!$F$5)) -> 66.417359 | AL6: =IF(AK6>=Assessments!$G$2*1.2, 3, IF(AK6>=Assessments!$G$2, 2, 1)) -> 2 | AM6: =((COs!$J$2 * C6 + COs!$J$3 * E6 + COs!$J$4 * G6 + COs!$J$5 * I6) / (COs!$J$2 * Assessments!$B$2 * Assessments!$C$2 + COs!$J$3 * Assessments!$B$3 * Assessments!$D$3 + COs!$J$4 * Assessments!$B$4 * Assessments!$E$4 + COs!$J$5 * Assessments!$B$5 * Assessments!$F$5)) -> 28.09009 | AN6: =IF(AM6>=Assessments!$G$2*1.2, 3, IF(AM6>=Assessments!$G$2, 2, 1)) -> 1 | AO6: =((COs!$K$2 * C6 + COs!$K$3 * E6 + COs!$K$4 * G6 + COs!$K$5 * I6) / (COs!$K$2 * Assessments!$B$2 * Assessments!$C$2 + COs!$K$3 * Assessments!$B$3 * Assessments!$D$3 + COs!$K$4 * Assessments!$B$4 * Assessments!$E$4 + COs!$K$5 * Assessments!$B$5 * Assessments!$F$5)) -> 28.09009 | AP6: =IF(AO6>=Assessments!$G$2*1.2, 3, IF(AO6>=Assessments!$G$2, 2, 1)) -> 1 | AQ6: =((COs!$L$2 * C6 + COs!$L$3 * E6 + COs!$L$4 * G6 + COs!$L$5 * I6) / (COs!$L$2 * Assessments!$B$2 * Assessments!$C$2 + COs!$L$3 * Assessments!$B$3 * Assessments!$D$3 + COs!$L$4 * Assessments!$B$4 * Assessments!$E$4 + COs!$L$5 * Assessments!$B$5 * Assessments!$F$5)) -> 37.453453 | AR6: =IF(AQ6>=Assessments!$G$2*1.2, 3, IF(AQ6>=Assessments!$G$2, 2, 1)) -> 1 | AS6: =((COs!$M$2 * C6 + COs!$M$3 * E6 + COs!$M$4 * G6 + COs!$M$5 * I6) / (COs!$M$2 * Assessments!$B$2 * Assessments!$C$2 + COs!$M$3 * Assessments!$B$3 * Assessments!$D$3 + COs!$M$4 * Assessments!$B$4 * Assessments!$E$4 + COs!$M$5 * Assessments!$B$5 * Assessments!$F$5)) -> 37.453453 | AT6: =IF(AS6>=Assessments!$G$2*1.2, 3, IF(AS6>=Assessments!$G$2, 2, 1)) -> 1 | AU6: =((COs!$N$2 * C6 + COs!$N$3 * E6 + COs!$N$4 * G6 + COs!$N$5 * I6) / (COs!$N$2 * Assessments!$B$2 * Assessments!$C$2 + COs!$N$3 * Assessments!$B$3 * Assessments!$D$3 + COs!$N$4 * Assessments!$B$4 * Assessments!$E$4 + COs!$N$5 * Assessments!$B$5 * Assessments!$F$5)) -> 51.73959 | AV6: =IF(AU6>=Assessments!$G$2*1.2, 3, IF(AU6>=Assessments!$G$2, 2, 1)) -> 1 | AW6: =((COs!$O$2 * C6 + COs!$O$3 * E6 + COs!$O$4 * G6 + COs!$O$5 * I6) / (COs!$O$2 * Assessments!$B$2 * Assessments!$C$2 + COs!$O$3 * Assessments!$B$3 * Assessments!$D$3 + COs!$O$4 * Assessments!$B$4 * Assessments!$E$4 + COs!$O$5 * Assessments!$B$5 * Assessments!$F$5)) -> 38.000857 | AX6: =IF(AW6>=Assessments!$G$2*1.2, 3, IF(AW6>=Assessments!$G$2, 2, 1)) -> 1 | AY6: =((COs!$P$2 * C6 + COs!$P$3 * E6 + COs!$P$4 * G6 + COs!$P$5 * I6) / (COs!$P$2 * Assessments!$B$2 * Assessments!$C$2 + COs!$P$3 * Assessments!$B$3 * Assessments!$D$3 + COs!$P$4 * Assessments!$B$4 * Assessments!$E$4 + COs!$P$5 * Assessments!$B$5 * Assessments!$F$5)) -> 33.708108 | AZ6: =IF(AY6>=Assessments!$G$2*1.2, 3, IF(AY6>=Assessments!$G$2, 2, 1)) -> 1
